Workbook

Sheet Ringkasan
B2: RINGKASAN AUDIT DATA AWAL
B3: Dataset: crime_incidents_messy.csv
B5: Metrik | C5: Nilai
B6: Jumlah Data (baris) | C6: =ROWS('Data Mentah'!A2:A5251) -> 5250
B7: Jumlah Kolom | C7: =COLUMNS('Data Mentah'!A1:AG1) -> 33
B8: Jumlah Baris Duplikat Penuh | C8: 200
B9: Jumlah incident_id Duplikat | C9: 200
B10: Total Sel Kosong (missing) | C10: =SUM('Missing Value'!C2:C34) -> 16478
B11: Total Sel Dataset | C11: =ROWS('Data Mentah'!A2:A5251)*COLUMNS('Data Mentah'!A1:AG1) -> 173250
B12: Persentase Missing Keseluruhan (%) | C12: =ROUND(C10/C11*100,2) -> 9.51
B13: Jumlah Kolom Mengandung Missing Value | C13: =COUNTIF('Missing Value'!C2:C34,">0") -> 24
B16: Catatan:
B17: Jumlah baris duplikat dihitung menggunakan df.duplicated().sum() pada Notebook Audit.ipynb, karena deteksi duplikat baris penuh (33 kolom) lebih efisien dilakukan di Python dibanding formula spreadsheet.

Sheet Missing Value
A1: No | B1: Kolom | C1: Jumlah Missing | D1: Persentase (%)
A2: 1 | B2: incident_id | C2: =COUNTBLANK('Data Mentah'!A2:A5251) -> 0 | D2: =ROUND(C2/ROWS('Data Mentah'!A2:A5251)*100,2) -> 0
A3: 2 | B3: crime_type | C3: =COUNTBLANK('Data Mentah'!B2:B5251) -> 0 | D3: =ROUND(C3/ROWS('Data Mentah'!A2:A5251)*100,2) -> 0
A4: 3 | B4: district | C4: =COUNTBLANK('Data Mentah'!C2:C5251) -> 0 | D4: =ROUND(C4/ROWS('Data Mentah'!A2:A5251)*100,2) -> 0
A5: 4 | B5: city | C5: =COUNTBLANK('Data Mentah'!D2:D5251) -> 0 | D5: =ROUND(C5/ROWS('Data Mentah'!A2:A5251)*100,2) -> 0
A6: 5 | B6: state | C6: =COUNTBLANK('Data Mentah'!E2:E5251) -> 0 | D6: =ROUND(C6/ROWS('Data Mentah'!A2:A5251)*100,2) -> 0
A7: 6 | B7: address | C7: =COUNTBLANK('Data Mentah'!F2:F5251) -> 0 | D7: =ROUND(C7/ROWS('Data Mentah'!A2:A5251)*100,2) -> 0
A8: 7 | B8: latitude | C8: =COUNTBLANK('Data Mentah'!G2:G5251) -> 258 | D8: =ROUND(C8/ROWS('Data Mentah'!A2:A5251)*100,2) -> 4.91
A9: 8 | B9: longitude | C9: =COUNTBLANK('Data Mentah'!H2:H5251) -> 289 | D9: =ROUND(C9/ROWS('Data Mentah'!A2:A5251)*100,2) -> 5.5
A10: 9 | B10: incident_datetime | C10: =COUNTBLANK('Data Mentah'!I2:I5251) -> 340 | D10: =ROUND(C10/ROWS('Data Mentah'!A2:A5251)*100,2) -> 6.48
A11: 10 | B11: officer_id | C11: =COUNTBLANK('Data Mentah'!J2:J5251) -> 0 | D11: =ROUND(C11/ROWS('Data Mentah'!A2:A5251)*100,2) -> 0
A12: 11 | B12: officer_first_name | C12: =COUNTBLANK('Data Mentah'!K2:K5251) -> 0 | D12: =ROUND(C12/ROWS('Data Mentah'!A2:A5251)*100,2) -> 0
A13: 12 | B13: officer_last_name | C13: =COUNTBLANK('Data Mentah'!L2:L5251) -> 0 | D13: =ROUND(C13/ROWS('Data Mentah'!A2:A5251)*100,2) -> 0
A14: 13 | B14: badge_number | C14: =COUNTBLANK('Data Mentah'!M2:M5251) -> 312 | D14: =ROUND(C14/ROWS('Data Mentah'!A2:A5251)*100,2) -> 5.94
A15: 14 | B15: suspect_id | C15: =COUNTBLANK('Data Mentah'!N2:N5251) -> 810 | D15: =ROUND(C15/ROWS('Data Mentah'!A2:A5251)*100,2) -> 15.43
A16: 15 | B16: suspect_first_name | C16: =COUNTBLANK('Data Mentah'!O2:O5251) -> 810 | D16: =ROUND(C16/ROWS('Data Mentah'!A2:A5251)*100,2) -> 15.43
A17: 16 | B17: suspect_last_name | C17: =COUNTBLANK('Data Mentah'!P2:P5251) -> 810 | D17: =ROUND(C17/ROWS('Data Mentah'!A2:A5251)*100,2) -> 15.43
A18: 17 | B18: suspect_age | C18: =COUNTBLANK('Data Mentah'!Q2:Q5251) -> 1097 | D18: =ROUND(C18/ROWS('Data Mentah'!A2:A5251)*100,2) -> 20.9
A19: 18 | B19: suspect_gender | C19: =COUNTBLANK('Data Mentah'!R2:R5251) -> 1413 | D19: =ROUND(C19/ROWS('Data Mentah'!A2:A5251)*100,2) -> 26.91
A20: 19 | B20: suspect_race | C20: =COUNTBLANK('Data Mentah'!S2:S5251) -> 1601 | D20: =ROUND(C20/ROWS('Data Mentah'!A2:A5251)*100,2) -> 30.5
A21: 20 | B21: victim_id | C21: =COUNTBLANK('Data Mentah'!T2:T5251) -> 257 | D21: =ROUND(C21/ROWS('Data Mentah'!A2:A5251)*100,2) -> 4.9
A22: 21 | B22: victim_first_name | C22: =COUNTBLANK('Data Mentah'!U2:U5251) -> 257 | D22: =ROUND(C22/ROWS('Data Mentah'!A2:A5251)*100,2) -> 4.9
A23: 22 | B23: victim_last_name | C23: =COUNTBLANK('Data Mentah'!V2:V5251) -> 257 | D23: =ROUND(C23/ROWS('Data Mentah'!A2:A5251)*100,2) -> 4.9
A24: 23 | B24: victim_age | C24: =COUNTBLANK('Data Mentah'!W2:W5251) -> 562 | D24: =ROUND(C24/ROWS('Data Mentah'!A2:A5251)*100,2) -> 10.7
A25: 24 | B25: victim_gender | C25: =COUNTBLANK('Data Mentah'!X2:X5251) -> 1000 | D25: =ROUND(C25/ROWS('Data Mentah'!A2:A5251)*100,2) -> 19.05
A26: 25 | B26: victim_phone | C26: =COUNTBLANK('Data Mentah'!Y2:Y5251) -> 1056 | D26: =ROUND(C26/ROWS('Data Mentah'!A2:A5251)*100,2) -> 20.11
A27: 26 | B27: weapon_used | C27: =COUNTBLANK('Data Mentah'!Z2:Z5251) -> 970 | D27: =ROUND(C27/ROWS('Data Mentah'!A2:A5251)*100,2) -> 18.48
A28: 27 | B28: severity | C28: =COUNTBLANK('Data Mentah'!AA2:AA5251) -> 355 | D28: =ROUND(C28/ROWS('Data Mentah'!A2:A5251)*100,2) -> 6.76
A29: 28 | B29: case_status | C29: =COUNTBLANK('Data Mentah'!AB2:AB5251) -> 731 | D29: =ROUND(C29/ROWS('Data Mentah'!A2:A5251)*100,2) -> 13.92
A30: 29 | B30: resolution | C30: =COUNTBLANK('Data Mentah'!AC2:AC5251) -> 951 | D30: =ROUND(C30/ROWS('Data Mentah'!A2:A5251)*100,2) -> 18.11
A31: 30 | B31: num_arrests | C31: =COUNTBLANK('Data Mentah'!AD2:AD5251) -> 333 | D31: =ROUND(C31/ROWS('Data Mentah'!A2:A5251)*100,2) -> 6.34
A32: 31 | B32: property_loss_usd | C32: =COUNTBLANK('Data Mentah'!AE2:AE5251) -> 436 | D32: =ROUND(C32/ROWS('Data Mentah'!A2:A5251)*100,2) -> 8.3
A33: 32 | B33: reported_online | C33: =COUNTBLANK('Data Mentah'!AF2:AF5251) -> 504 | D33: =ROUND(C33/ROWS('Data Mentah'!A2:A5251)*100,2) -> 9.6
A34: 33 | B34: notes | C34: =COUNTBLANK('Data Mentah'!AG2:AG5251) -> 1069 | D34: =ROUND(C34/ROWS('Data Mentah'!A2:A5251)*100,2) -> 20.36

Sheet Tipe Data
A1: No | B1: Kolom | C1: Tipe Data (pandas) | D1: Jumlah Non-Null | E1: Keterangan
A2: 1 | B2: incident_id | C2: str | D2: =COUNTA('Data Mentah'!A2:A5251) -> 5250
A3: 2 | B3: crime_type | C3: str | D3: =COUNTA('Data Mentah'!B2:B5251) -> 5250
A4: 3 | B4: district | C4: str | D4: =COUNTA('Data Mentah'!C2:C5251) -> 5250
A5: 4 | B5: city | C5: str | D5: =COUNTA('Data Mentah'!D2:D5251) -> 5250
A6: 5 | B6: state | C6: str | D6: =COUNTA('Data Mentah'!E2:E5251) -> 5250
A7: 6 | B7: address | C7: str | D7: =COUNTA('Data Mentah'!F2:F5251) -> 5250
A8: 7 | B8: latitude | C8: float64 | D8: =COUNTA('Data Mentah'!G2:G5251) -> 4992
A9: 8 | B9: longitude | C9: float64 | D9: =COUNTA('Data Mentah'!H2:H5251) -> 4961
A10: 9 | B10: incident_datetime | C10: str | D10: =COUNTA('Data Mentah'!I2:I5251) -> 4910 | E10: Perlu dikonversi ke datetime; format tanggal pada data mentah tidak seragam
A11: 10 | B11: officer_id | C11: str | D11: =COUNTA('Data Mentah'!J2:J5251) -> 5250
A12: 11 | B12: officer_first_name | C12: str | D12: =COUNTA('Data Mentah'!K2:K5251) -> 5250
A13: 12 | B13: officer_last_name | C13: str | D13: =COUNTA('Data Mentah'!L2:L5251) -> 5250
A14: 13 | B14: badge_number | C14: float64 | D14: =COUNTA('Data Mentah'!M2:M5251) -> 4938
A15: 14 | B15: suspect_id | C15: str | D15: =COUNTA('Data Mentah'!N2:N5251) -> 4440
A16: 15 | B16: suspect_first_name | C16: str | D16: =COUNTA('Data Mentah'!O2:O5251) -> 4440
A17: 16 | B17: suspect_last_name | C17: str | D17: =COUNTA('Data Mentah'!P2:P5251) -> 4440
A18: 17 | B18: suspect_age | C18: float64 | D18: =COUNTA('Data Mentah'!Q2:Q5251) -> 4153
A19: 18 | B19: suspect_gender | C19: str | D19: =COUNTA('Data Mentah'!R2:R5251) -> 3837
A20: 19 | B20: suspect_race | C20: str | D20: =COUNTA('Data Mentah'!S2:S5251) -> 3649
A21: 20 | B21: victim_id | C21: str | D21: =COUNTA('Data Mentah'!T2:T5251) -> 4993
A22: 21 | B22: victim_first_name | C22: str | D22: =COUNTA('Data Mentah'!U2:U5251) -> 4993
A23: 22 | B23: victim_last_name | C23: str | D23: =COUNTA('Data Mentah'!V2:V5251) -> 4993
A24: 23 | B24: victim_age | C24: float64 | D24: =COUNTA('Data Mentah'!W2:W5251) -> 4688
A25: 24 | B25: victim_gender | C25: str | D25: =COUNTA('Data Mentah'!X2:X5251) -> 4250
A26: 25 | B26: victim_phone | C26: str | D26: =COUNTA('Data Mentah'!Y2:Y5251) -> 4194
A27: 26 | B27: weapon_used | C27: str | D27: =COUNTA('Data Mentah'!Z2:Z5251) -> 4280
A28: 27 | B28: severity | C28: str | D28: =COUNTA('Data Mentah'!AA2:AA5251) -> 4895 | E28: Bercampur antara angka (1-4) dan teks (Low/Medium/High/Critical)
A29: 28 | B29: case_status | C29: str | D29: =COUNTA('Data Mentah'!AB2:AB5251) -> 4519
A30: 29 | B30: resolution | C30: str | D30: =COUNTA('Data Mentah'!AC2:AC5251) -> 4299
A31: 30 | B31: num_arrests | C31: float64 | D31: =COUNTA('Data Mentah'!AD2:AD5251) -> 4917
A32: 31 | B32: property_loss_usd | C32: str | D32: =COUNTA('Data Mentah'!AE2:AE5251) -> 4814 | E32: Seharusnya numerik (float), masih tersimpan sebagai teks/object karena format tidak konsisten
A33: 32 | B33: reported_online | C33: str | D33: =COUNTA('Data Mentah'!AF2:AF5251) -> 4746 | E33: Bercampur antara True/False, Yes/No, dan 1/0
A34: 33 | B34: notes | C34: str | D34: =COUNTA('Data Mentah'!AG2:AG5251) -> 4181

Sheet Duplicate
B2: PEMERIKSAAN DATA DUPLIKAT
B4: Jumlah baris duplikat penuh (df.duplicated().sum()) | D4: 200
B5: Jumlah incident_id duplikat | D5: 200
B7: Contoh incident_id yang terduplikasi:
B8: No | C8: incident_id
B9: 1 | C9: INC000008
B10: 2 | C10: INC000015
B11: 3 | C11: INC000016
B12: 4 | C12: INC000019
B13: 5 | C13: INC000024
B14: 6 | C14: INC000027
B15: 7 | C15: INC000043
B16: 8 | C16: INC000050
B17: 9 | C17: INC000052
B18: 10 | C18: INC000055
B19: 11 | C19: INC000067
B20: 12 | C20: INC000081
... B23: 15 | C23: INC000133

Sheet Permasalahan Ditemukan
B2: PERMASALAHAN YANG DITEMUKAN
A4: No | B4: Kolom | C4: Permasalahan | D4: Jumlah/Detail
A5: 1 | B5: crime_type | C5: 182 nilai unik mentah; masih 68 kategori setelah normalisasi huruf kecil & spasi (singkatan & typo berbeda, mis. 'B&E' vs 'Breaking & Entering', 'DV' vs 'Domestic Violence', 'Homocide') | D5: 182 → 68 kategori
A6: 2 | B6: district | C6: 131 nilai unik mentah; masih 16 kategori setelah normalisasi (singkatan seperti 'nor', 'sou', 'mid', 'cen', 'wes') | D6: 131 → 16 kategori
A7: 3 | B7: severity | C7: Bercampur format angka (1-4) dan teks (Low/Medium/High/Critical) dengan variasi huruf besar/kecil dan singkatan (Med, Crit) | D7: 15 variasi nilai
A8: 4 | B8: case_status | C8: Variasi huruf besar/kecil dan typo (mis. 'Investgation', 'Pendng') | D8: 13 variasi nilai
A9: 5 | B9: resolution | C9: Variasi penulisan (mis. 'Arres Made' vs 'Arrest Made') | D9: 10 variasi nilai
A10: 6 | B10: reported_online | C10: Bercampur representasi boolean: True/False, Yes/No, 1/0 | D10: 11 variasi nilai
A11: 7 | B11: weapon_used | C11: Variasi huruf besar/kecil (mis. 'KNIFE' vs 'Knife' vs 'knife') | D11: 14 variasi nilai
A12: 8 | B12: suspect_gender / victim_gender | C12: Variasi huruf besar/kecil dan singkatan (M/F vs Male/Female) | D12: 13 variasi nilai per kolom
A13: 9 | B13: suspect_race | C13: Variasi huruf besar/kecil (mis. 'White' vs 'white') | D13: 11 variasi nilai
A14: 10 | B14: suspect_age | C14: Terdapat nilai negatif dan nilai di atas 120 tahun (tidak logis) | D14: 173 negatif, 160 nilai >120
A15: 11 | B15: victim_age | C15: Terdapat nilai negatif dan nilai di atas 120 tahun (tidak logis) | D15: 223 negatif, 185 nilai >120
A16: 12 | B16: num_arrests | C16: Terdapat nilai negatif (tidak logis untuk jumlah penangkapan) | D16: 184 baris
... A19: 15 | B19: incident_datetime | C19: Tiga format tanggal berbeda tercampur dalam satu kolom | D19: ISO datetime, DD-MM-YYYY, MM/DD/YYYY HH:MM

Sheet Data Mentah
A1: incident_id | B1: crime_type | C1: district | D1: city | E1: state | F1: address | G1: latitude | H1: longitude | I1: incident_datetime | J1: officer_id | K1: officer_first_name | L1: officer_last_name | M1: badge_number | N1: suspect_id | O1: suspect_first_name | P1: suspect_last_name | Q1: suspect_age | R1: suspect_gender | S1: suspect_race | T1: victim_id | U1: victim_first_name | V1: victim_last_name | W1: victim_age | X1: victim_gender | Y1: victim_phone | Z1: weapon_used | AA1: severity | AB1: case_status | AC1: resolution | AD1: num_arrests | AE1: property_loss_usd | AF1: reported_online | AG1: notes
A2: INC001115 | B2: asslt | C2: Sou | D2: Maplewood | E2: GA | F2: 2830 Cedar Lane | G2: 170.2841 | H2: -77.50071 | I2: 2024-04-16 08:45:03 | J2: OFF0078 | K2: Emily | L2: Davis | M2: 1342 | N2: SUS00281 | O2: Barbara | P2: Thomas | Q2: 51 | R2: MALE | S2: asian | T2: VIC00642 | U2: Robert | V2: Torres | W2: 51 | X2: Unknown | Y2: 6223265920 | Z2: Firearm | AA2: 2 | AB2: Open | AC2: No Arrest | AF2: True | AG2: Incident at 2830 Cedar Lane. Officer responded at scene.
A3: INC004706 | B3: burglary | C3: southeast | D3: Maplewood | E3: OH | F3: 2361 Park Rd | G3: 29.422717 | H3: -77.167016 | I3: 2022-01-11 22:03:29 | J3: OFF0059 | K3: Michelle | L3: Green | M3: 5133 | N3: SUS00376 | O3: Barbara | P3: Harris | Q3: -28 | R3: Other | S3: Black | T3: VIC00262 | U3: John | V3: Martin | W3: 231 | Y3: 241-973-4826 | Z3: Firearm | AA3: 3 | AD3: 2 | AE3: 44839.49 | AF3: yes | AG3: Incident at 2361 Park Rd. Officer responded at scene.
A4: INC002249 | B4: Homocide | C4: Southwest | D4: Lakewood | E4: AZ | F4: 1067 Main St | G4: 39.41146 | H4: -98.615298 | I4: 2022-04-14 11:39:24 | J4: OFF0088 | K4: Michael | L4: White | M4: 7781 | N4: SUS00560 | O4: Richard | P4: Scott | Q4: 19 | R4: F | S4: asian | T4: VIC00518 | U4: Richard | V4: Hill | W4: 29 | X4: Other | Y4: 244-584-7696 | Z4: KNIFE | AA4: 1 | AB4: CLOSED | AC4: warning | AD4: 2 | AE4: 15963.38 | AF4: YES | AG4: Incident at 1067 Main St. Officer responded at scene.
A5: INC000021 | B5: Property Damage | C5: Cen | D5: Springfield | E5: AZ | F5: 4713 Washington Ave | G5: 28.633439 | H5: -99.030051 | I5: 2020-12-09 15:14:24 | J5: OFF0077 | K5: Chris | L5: Jackson | M5: 5097 | N5: SUS00468 | O5: Michael | P5: Thomas | Q5: 262 | R5: MALE | S5: Black | T5: VIC00243 | U5: Susan | V5: Young | W5: 243 | Y5: 5021227484 | Z5: hands | AA5: Low | AB5: Resolved | AD5: 5 | AE5: 48680.14 | AF5: False | AG5: Incident at 4713 Washington Ave. Officer responded at scene.
A6: INC000488 | B6: Domestc Violence | C6: North | D6: Lakewood | E6: PA | F6: 1371 River Rd | G6: 34.21785 | H6: -121.61473 | I6: 2021-07-24 20:08:13 | J6: OFF0083 | K6: Susan | L6: Flores | M6: 6220 | N6: SUS00751 | O6: Thomas | P6: Jackson | Q6: 75 | R6: female | S6: white | T6: VIC00512 | U6: Thomas | V6: Thomas | W6: 51 | X6: M | Y6: 9698766873 | Z6: Unarmed | AA6: MEDIUM | AB6: Closed | AC6: Warning Issued | AD6: 2 | AE6: 23513.01 | AF6: YES
A7: INC000661 | B7: Breaking & Entering | C7: East | D7: Hillcrest | E7: CA | F7: 3551 Elm Blvd | G7: 44.438603 | H7: -101.77512 | I7: 05-03-2020 | J7: OFF0089 | K7: Jennifer | L7: Green | M7: 7082 | N7: SUS00454 | O7: James | P7: Lee | Q7: 73 | S7: White | T7: VIC00473 | U7: Anthony | V7: Wilson | W7: 15 | Y7: 590-332-6488 | Z7: Blunt Object | AA7: high | AB7: under investigation | AC7: arrest made | AD7: 1 | AF7: YES | AG7: Incident at 3551 Elm Blvd. Officer responded at scene.
A8: INC001727 | B8: robbery | C8: southeast | D8: Maplewood | E8: TX | F8: 7394 Cedar Lane | G8: 38.525825 | H8: -90.100219 | I8: 2021-10-03 05:17:02 | J8: OFF0141 | K8: Jennifer | L8: Harris | M8: 7747 | N8: SUS00623 | O8: Carol | P8: Harris | Q8: 58 | R8: Female | S8: Unknown | T8: VIC00429 | U8: Mary | V8: Walker | W8: 72 | X8: female | Y8: 431-579-6170 | Z8: Blunt Object | AB8: CLOSED | AC8: warning | AD8: 3 | AF8: YES | AG8: Incident at 7394 Cedar Lane. Officer responded at scene.
A9: INC003981 | B9: manslaughter | C9: midtown | D9: Centerville | E9: IL | F9: 1610 River Rd | G9: 46.854678 | H9: -99.512808 | I9: 2023-09-30 14:49:01 | J9: OFF0008 | K9: Karen | L9: Hall | M9: 7869 | N9: SUS00533 | O9: Jennifer | P9: Taylor | Q9: 73 | R9: MALE | S9: White | T9: VIC00904 | U9: David | V9: Torres | X9: female | Y9: 587-505-1798 | AA9: 1 | AB9: open | AC9: No Arrest | AD9: 2 | AE9: 19075.36 | AF9: no | AG9: Incident at 1610 River Rd. Officer responded at scene.
A10: INC001205 | B10: B&E | C10: East | D10: Centerville | E10: OH | F10: 378 Oak Ave | G10: 38.869063 | H10: -114.38575 | I10: 2021-01-22 02:37:24 | J10: OFF0034 | K10: Daniel | L10: Jackson | M10: 8229 | N10: SUS00320 | O10: Robert | P10: Hill | Q10: 26 | R10: m | S10: Hispanic | T10: VIC00093 | U10: Mary | V10: Lee | W10: 55 | X10: Other | Y10: 3956212676 | Z10: hands | AA10: Crit | AB10: under investigation | AC10: warning | AD10: 0 | AE10: 34452.47 | AF10: yes | AG10: Incident at 378 Oak Ave. Officer responded at scene.
A11: INC000972 | B11: Homocide | C11: northeast | D11: Riverside | E11: IL | F11: 8974 Park Rd | G11: 42.018768 | H11: -72.384742 | I11: 2021-03-29 04:16:18 | J11: OFF0093 | K11: Mary | L11: Thompson | M11: 7242 | T11: VIC00859 | U11: Michelle | V11: Hill | W11: 10 | Y11: 376-440-3132 | Z11: Rifle | AA11: 2 | AB11: Investgation | AD11: 5 | AE11: 35339.52
A12: INC002898 | B12: Property Damage | C12: CENTRAL | D12: Oakdale | E12: NY | F12: 9798 Elm Blvd | G12: 36.632099 | H12: -104.1963 | I12: 2020-03-03 06:46:12 | J12: OFF0035 | K12: John | L12: Jones | M12: 9036 | N12: SUS00005 | O12: Ashley | P12: Harris | Q12: 49 | R12: FEMALE | S12: BLACK | T12: VIC00682 | U12: Mark | V12: Young | W12: 47 | Y12: 596-444-9767 | AA12: High | AB12: Under Investigation | AD12: 0 | AE12: 27438.67 | AF12: False | AG12: Incident at 9798 Elm Blvd. Officer responded at scene.
A13: INC003264 | B13: Narcotics | C13: central | D13: Fairview | E13: AZ | F13: 8650 Elm Blvd | G13: 46.424282 | H13: -120.99668 | I13: 2018-09-09 02:11:36 | J13: OFF0111 | K13: Donna | L13: Thompson | M13: 4688 | T13: VIC00084 | U13: Anthony | V13: Nguyen | W13: 35 | X13: Unknown | Y13: 855-624-8658 | Z13: Bat | AA13: low | AB13: OPEN | AD13: -5 | AE13: 41738.8 | AF13: Yes
A14: INC003052 | B14: Burglry | C14: Eas | D14: Hillcrest | E14: OH | F14: 5420 River Rd | G14: 47.020966 | H14: -83.072251 | I14: 2020-07-04 13:31:15 | J14: OFF0104 | K14: James | L14: Taylor | N14: SUS00783 | O14: Anthony | P14: Martin | Q14: 33 | R14: M | S14: Asian | T14: VIC00960 | U14: Mark | V14: Taylor | W14: 55 | X14: male | Y14: 832-278-8736 | Z14: Rifle | AA14: Critical | AC14: warning | AD14: 2 | AE14: -34291.84 | AF14: No | AG14: Incident at 5420 River Rd. Officer responded at scene.
A15: INC000524 | B15: THEFT | C15: Northeast | D15: Centerville | E15: FL | F15: 6121 Oak Ave | G15: 44.872436 | H15: -106.85205 | I15: 2023-07-30 09:05:34 | J15: OFF0014 | K15: Joseph | L15: Smith | M15: 4335 | N15: SUS00236 | O15: Thomas | P15: Jones | Q15: 162 | R15: female | S15: hispanic | T15: VIC00569 | U15: Robert | V15: Scott | W15: -41 | X15: male | Y15: 655-760-3556 | Z15: Knife | AA15: 4 | AB15: Resolved | AD15: 2 | AE15: 3201.56 | AF15: 1 | AG15: Incident at 6121 Oak Ave. Officer responded at scene.
A16: INC000560 | B16: Fraudulent Activity | C16: midtown | D16: Centerville | E16: OH | F16: 5094 Main St | G16: 28.121432 | H16: -84.979481 | I16: 04/01/2020 03:09 | J16: OFF0046 | K16: Donna | L16: Thompson | M16: 8121 | N16: SUS00074 | O16: Daniel | P16: Thompson | Q16: 52 | R16: Other | S16: white | T16: VIC00821 | U16: Barbara | V16: Johnson | W16: 26 | X16: M | Z16: Pistol | AA16: 3 | AC16: warning | AD16: 3 | AE16: 37228.41 | AF16: 1 | AG16: Incident at 5094 Main St. Officer responded at scene.
A17: INC000812 | B17: Drug Offense | C17: Nor | D17: Riverside | E17: CA | F17: 5556 River Rd | G17: 47.561353 | H17: -85.069404 | I17: 2020-11-26 07:15:19 | J17: OFF0133 | K17: emily | L17: Nguyen | M17: 8079 | N17: SUS00606 | O17: Chris | P17: Garcia | Q17: 21 | R17: m | S17: Asian | T17: VIC00071 | U17: Daniel | V17: Jackson | W17: 82 | X17: female | Y17: 628-122-3246 | Z17: Blunt Object | AA17: High | AB17: OPEN | AC17: NO ARREST | AE17: 41473.0 | AF17: YES
A18: INC003999 | B18: Armed Robbery | C18: Southeast | D18: Centerville | E18: PA | F18: 6637 Lincoln St | G18: 25.262347 | H18: -73.445871 | I18: 2021-11-05 17:21:18 | J18: OFF0097 | K18: Ashley | L18: Davis | M18: 6651 | N18: SUS00776 | O18: Joseph | P18: Brown | Q18: 18 | R18: male | S18: BLACK | T18: VIC00676 | U18: Linda | V18: Nguyen | X18: Female | Y18: 897-102-9006 | Z18: Knife | AB18: Pendng | AD18: 3 | AF18: 1 | AG18: Incident at 6637 Lincoln St. Officer responded at scene.
A19: INC003972 | B19: Arsen | C19: SOUTHWEST | D19: Centerville | E19: IL | F19: 3221 Cedar Lane | G19: 25.80811 | H19: -106.36895 | I19: 2022-10-07 17:15:25 | J19: OFF0141 | K19: Charles | L19: Nguyen | M19: 7634 | T19: VIC00846 | U19: Donna | V19: Jackson | W19: 82 | X19: F | Y19: 924-985-8530 | AA19: CRITICAL | AB19: Pending | AC19: Warning Issued | AD19: 4 | AF19: yes | AG19: Incident at 3221 Cedar Lane. Officer responded at scene.
A20: INC000949 | B20: Abduction | C20: North | D20: Maplewood | E20: CA | F20: 5783 Main St | G20: 40.614362 | H20: -80.606867 | I20: 2024-11-23 19:30:48 | J20: OFF0020 | K20: Susan | L20: Walker | M20: 2599 | N20: SUS00636 | O20: Richard | P20: Wright | Q20: 57 | T20: VIC00228 | U20: Mary | V20: Walker | W20: 49 | X20: MALE | AA20: Medium | AC20: No Arrest | AD20: 2 | AE20: 31931.65 | AG20: Incident at 5783 Main St. Officer responded at scene.
A21: INC002839 | B21: Graffiti | C21: East | D21: Hillcrest | E21: FL | F21: 5563 Lincoln St | G21: 31.366741 | H21: -81.476181 | I21: 2018-08-26 04:50:54 | J21: OFF0050 | K21: John | L21: Smith | M21: 9830 | N21: SUS00294 | O21: Michael | P21: Jones | Q21: 51 | R21: F | S21: Hispanic | T21: VIC00850 | U21: David | V21: Williams | X21: m | Z21: Bat | AA21: 2 | AB21: Closed | AC21: Warning Issued | AD21: 0 | AE21: 6546.79 | AG21: Incident at 5563 Lincoln St. Officer responded at scene.
A22: INC002859 | B22: Trespass | C22: Mid | D22: Maplewood | E22: PA | F22: 1522 Lincoln St | G22: 43.213574 | H22: -112.53265 | I22: 2019-10-15 08:23:45 | J22: OFF0020 | K22: Joseph | L22: Walker | M22: 6621 | N22: SUS00207 | O22: Mary | P22: Brown | Q22: 42 | R22: Female | S22: Hispanic | T22: VIC00225 | U22: Patricia | V22: Green | W22: 12 | X22: MALE | Y22: 527-108-7397 | Z22: Knife | AA22: low | AB22: closed | AC22: Dismissed | AD22: 5 | AE22: 26845.31 | AF22: 1 | AG22: Incident at 1522 Lincoln St. Officer responded at scene.
A23: INC004651 | B23: CYBER CRIME | C23: EAST | D23: Oakdale | E23: OH | F23: 3806 Washington Ave | G23: 39.701184 | H23: 60.9112 | I23: 2020-03-20 14:28:36 | J23: OFF0059 | K23: Sarah | L23: Martin | M23: 5314 | N23: SUS00385 | O23: James | P23: Young | Q23: 35 | R23: Male | S23: BLACK | T23: VIC00777 | U23: Donna | V23: Young | W23: 55 | X23: f | Y23: 701-395-6824 | Z23: firearm | AA23: 4 | AB23: Open | AC23: warning | AD23: 3 | AE23: 2167.35 | AF23: no | AG23: Incident at 3806 Washington Ave. Officer responded at scene.
A24: INC003793 | B24: Armed Robbery | C24: South | D24: Lakewood | E24: CA | F24: 3852 River Rd | G24: 35.044905 | H24: -83.999129 | I24: 2019-01-04 05:16:46 | J24: OFF0064 | K24: Jessica | L24: Walker | M24: 9763 | N24: SUS00630 | O24: Donna | P24: Harris | R24: male | S24: BLACK | T24: VIC00208 | U24: Richard | V24: Anderson | X24: Male | Z24: Gun | AA24: MEDIUM | AB24: under investigation | AC24: Arrest Made | AD24: 3 | AE24: 38573.92 | AF24: NO | AG24: Incident at 3852 River Rd. Officer responded at scene.
A25: INC004688 | B25: trespassing | C25: Wes | D25: Lakewood | E25: PA | F25: 1550 Sunset Blvd | G25: 25.112438 | H25: -97.442801 | I25: 2021-08-28 15:30:49 | J25: OFF0094 | K25: Anthony | L25: Moore | M25: 2483 | N25: SUS00220 | O25: Robert | P25: Wright | Q25: 58 | R25: Other | S25: Unknown | T25: VIC00521 | U25: Mark | V25: Harris | W25: 33 | X25: f | Y25: 294-211-8872 | Z25: Bat | AA25: Med | AB25: Open | AC25: Arres Made | AD25: 1 | AE25: 8534.94 | AF25: True | AG25: Incident at 1550 Sunset Blvd. Officer responded at scene.
A26: INC003745 | B26: asslt | C26: Central | D26: Riverside | E26: NY | F26: 2767 River Rd | G26: 28.234244 | I26: 2018-01-24 15:33:18 | J26: OFF0018 | K26: James | L26: Lee | M26: 5491 | N26: SUS00769 | O26: Donna | P26: Thompson | Q26: 54 | R26: Unknown | S26: white | T26: VIC00116 | U26: Thomas | V26: Miller | W26: 74 | X26: FEMALE | Y26: 762-638-3161 | Z26: firearm | AA26: Low | AB26: Resolved | AC26: Arrest Made | AD26: 2 | AE26: 24970.35 | AF26: 0 | AG26: Incident at 2767 River Rd. Officer responded at scene.
A27: INC002571 | B27: Sexual Assault | C27: North | D27: Centerville | E27: AZ | F27: 4669 Washington Ave | G27: 25.148272 | H27: -93.057116 | I27: 2023-05-28 05:34:09 | J27: OFF0144 | K27: Michelle | L27: Flores | M27: 4616 | N27: SUS00376 | O27: James | P27: Thompson | Q27: 61 | R27: male | S27: Hispanic | T27: VIC00147 | U27: Susan | V27: Nguyen | W27: 292 | X27: Other | Z27: Knife | AD27: 3 | AF27: No | AG27: Incident at 4669 Washington Ave. Officer responded at scene.
A28: INC002592 | B28: FRAUD | C28: midtown | D28: Riverside | E28: PA | F28: 3360 Sunset Blvd | G28: 25.974863 | H28: -96.956091 | I28: 2020-08-15 12:17:24 | J28: OFF0082 | K28: Anthony | L28: Thompson | M28: 4313 | N28: SUS00733 | O28: Karen | P28: Green | Q28: 58 | R28: Female | S28: Black | T28: VIC00333 | U28: Barbara | V28: Johnson | W28: 64 | X28: m | Y28: (806) -68-2-4246 | Z28: Blunt Object | AA28: 2 | AB28: Closed | AC28: warning | AD28: 3 | AF28: NO | AG28: Incident at 3360 Sunset Blvd. Officer responded at scene.
A29: INC003754 | B29: theft/larceny | C29: Sou | D29: Maplewood | E29: FL | F29: 120 Oak Ave | G29: 34.995351 | H29: -74.532818 | I29: 2020-05-17 13:46:21 | J29: OFF0017 | K29: EMILY | L29: Brown | M29: 2857 | N29: SUS00615 | O29: Jennifer | P29: Martin | Q29: 57 | R29: MALE | S29: asian | T29: VIC00223 | U29: David | V29: Hill | W29: 41 | X29: MALE | Y29: 771-406-4573 | AA29: 4 | AB29: Pending | AC29: No Arrest | AD29: 0 | AE29: 483.77 | AF29: Yes | AG29: Incident at 120 Oak Ave. Officer responded at scene.
A30: INC003891 | B30: Narcotics | C30: Eas | D30: Centerville | E30: OH | F30: 393 Elm Blvd | G30: 108.6542 | H30: -89.43987 | I30: 2018-11-28 21:17:46 | J30: OFF0008 | K30: David | L30: Moore | M30: 3817 | N30: SUS00378 | O30: Sarah | P30: White | Q30: 31 | R30: F | S30: White | T30: VIC00734 | U30: Carol | V30: Wright | W30: 69 | X30: MALE | Y30: 486-955-5798 | Z30: Gun | AA30: 2 | AB30: Investgation | AC30: Arres Made | AD30: 2 | AE30: 29148.65 | AF30: NO
A31: INC001824 | B31: Trespass | C31: West | D31: Fairview | E31: PA | F31: 2876 River Rd | G31: 29.118935 | H31: -89.958829 | I31: 2019-07-14 02:11:20 | J31: OFF0069 | K31: John | L31: Anderson | M31: 2450 | N31: SUS00248 | O31: Ashley | P31: Johnson | Q31: 20 | R31: MALE | S31: Other | T31: VIC00621 | U31: Joseph | V31: Brown | W31: 36 | Y31: 917-543-5246 | Z31: Blunt Object | AA31: High | AB31: closed | AD31: 0 | AE31: 25983.21 | AF31: NO
A32: INC003739 | B32: Larceny | C32: East | D32: Springfield | E32: NC | F32: 6343 Sunset Blvd | G32: 44.749794 | H32: -73.947406 | I32: 2021-07-18 12:36:42 | J32: OFF0031 | K32: MICHELLE | L32: Martin | M32: 9056 | N32: SUS00344 | O32: Ashley | P32: Moore | Q32: 63 | R32: Male | S32: hispanic | T32: VIC00171 | U32: Daniel | V32: Taylor | W32: 43 | X32: male | AB32: Investgation | AC32: Warning Issued | AD32: 4 | AE32: 41970.69 | AF32: 0
A33: INC004507 | B33: arson | C33: West | D33: Maplewood | E33: NC | F33: 3637 Sunset Blvd | H33: -71.382964 | I33: 2020-06-19 16:28:10 | J33: OFF0129 | K33: Sarah | L33: Torres | M33: 9283 | N33: SUS00485 | O33: Susan | P33: Young | Q33: 42 | R33: f | S33: white | T33: VIC00335 | U33: Charles | V33: Martin | W33: 39 | X33: MALE | Y33: 983-275-9311 | Z33: Rifle | AB33: open | AC33: Arrest Made | AD33: 4 | AE33: 9134.49 | AF33: yes | AG33: Incident at 3637 Sunset Blvd. Officer responded at scene.
A34: INC002064 | B34: HOMICIDE | C34: Central | D34: Lakewood | E34: NC | F34: 4740 Washington Ave | G34: 44.042164 | I34: 2021-07-15 16:16:52 | J34: OFF0062 | K34: Donna | L34: Moore | M34: 3585 | N34: SUS00784 | O34: Joseph | P34: Jones | Q34: 32 | R34: male | S34: hispanic | T34: VIC00095 | U34: James | V34: Martin | W34: 33 | X34: f | Y34: 769-824-7668 | Z34: Bat | AA34: Critical | AC34: No Arrest | AD34: 4 | AE34: 42488.18 | AF34: yes | AG34: Incident at 4740 Washington Ave. Officer responded at scene.
A35: INC000769 | B35: Domestc Violence | C35: Wes | D35: Lakewood | E35: TX | F35: 2829 Main St | G35: 37.746236 | H35: -75.794667 | I35: 2020-04-01 01:39:34 | J35: OFF0141 | K35: Barbara | L35: Jones | M35: 7093 | N35: SUS00038 | O35: Nancy | P35: Thomas | Q35: 63 | R35: F | T35: VIC00620 | U35: Matthew | V35: White | W35: 74 | X35: female | Y35: 367-133-2010 | Z35: Blunt Object | AA35: low | AB35: Closed | AD35: 2 | AE35: 6820.75 | AF35: 1
A36: INC000900 | B36: Tresspassing | C36: Sou | D36: Oakdale | E36: FL | F36: 9483 Park Rd | G36: 26.435438 | I36: 2023-07-11 10:36:57 | J36: OFF0097 | K36: Patricia | L36: Anderson | M36: 1920 | T36: VIC00863 | U36: Richard | V36: Brown | W36: 60 | X36: Unknown | Y36: (255) -32-5-8101 | AA36: Low | AB36: closed | AC36: Arres Made | AD36: 0 | AE36: 13459.71 | AF36: No | AG36: Incident at 9483 Park Rd. Officer responded at scene.
A37: INC001193 | B37: TRESPASSING | C37: north | D37: Lakewood | E37: OH | F37: 4072 Oak Ave | G37: 40.228054 | H37: -75.920794 | I37: 2019-07-28 16:30:31 | J37: OFF0122 | K37: Jennifer | L37: Anderson | N37: SUS00293 | O37: Charles | P37: Torres | Q37: 38 | R37: M | S37: Unknown | T37: VIC00013 | U37: James | V37: White | W37: 83 | X37: M | Z37: hands | AA37: 2 | AB37: open | AC37: warning | AD37: 3 | AE37: 7425.53 | AF37: False | AG37: Incident at 4072 Oak Ave. Officer responded at scene.
A38: INC004887 | B38: Cybercrime | C38: Nor | D38: Riverside | E38: GA | F38: 1646 Oak Ave | G38: 34.412742 | H38: -85.854041 | I38: 2024-01-29 18:13:58 | J38: OFF0028 | K38: Daniel | L38: Flores | M38: 8763 | N38: SUS00238 | O38: Joseph | P38: Moore | Q38: 50 | S38: Hispanic | T38: VIC00699 | U38: Daniel | V38: Nguyen | W38: 17 | X38: Female | Y38: 624-369-6990 | AB38: Open | AC38: warning | AE38: 14830.28 | AF38: no | AG38: Incident at 1646 Oak Ave. Officer responded at scene.
A39: INC000015 | B39: asslt | C39: WEST | D39: Riverside | E39: GA | F39: 3034 Park Rd | G39: 29.976847 | H39: -96.821673 | I39: 2024-03-01 04:58:24 | J39: OFF0135 | K39: Nancy | L39: Moore | M39: 2647 | N39: SUS00199 | O39: Susan | P39: Garcia | Q39: 34 | R39: Male | T39: VIC00547 | U39: Mary | V39: Johnson | W39: 80 | X39: female | Y39: 914-229-9042 | Z39: Hands/Feet | AA39: 3 | AB39: Open | AC39: Arres Made | AD39: 2 | AE39: 23469.85 | AF39: 0 | AG39: Incident at 3034 Park Rd. Officer responded at scene.
A40: INC002728 | B40: BURGLARY | C40: west | D40: Oakdale | E40: PA | F40: 6010 Cedar Lane | G40: 38.426433 | H40: -119.11343 | I40: 2020-04-16 08:11:15 | J40: OFF0132 | K40: William | L40: Scott | M40: 5151 | N40: SUS00293 | O40: Michael | P40: Allen | Q40: 35 | R40: male | S40: Other | T40: VIC00765 | U40: Barbara | V40: Green | X40: MALE | Y40: 305-811-4555 | AA40: Low | AB40: Resolved | AD40: 0 | AE40: 3381.3 | AF40: 1 | AG40: Incident at 6010 Cedar Lane. Officer responded at scene.
...
