Workbook

Sheet Dataset
A1: Rank | B1: Name | C1: Platform | D1: Year | E1: Genre | F1: Publisher | G1: NA_Sales | H1: EU_Sales | I1: JP_Sales | J1: Other_Sales | K1: Global_Sales
A2: 1 | B2: Wii Sports | C2: Wii | D2: 2006 | E2: Sports | F2: Nintendo | G2: 41.49 | H2: 29.02 | I2: 3.77 | J2: 8.46 | K2: 82.74
A3: 2 | B3: Super Mario Bros. | C3: NES | D3: 1985 | E3: Platform | F3: Nintendo | G3: 29.08 | H3: 3.58 | I3: 6.81 | J3: 0.77 | K3: 40.24
A4: 3 | B4: Mario Kart Wii | C4: Wii | D4: 2008 | E4: Racing | F4: Nintendo | G4: 15.85 | H4: 12.88 | I4: 3.79 | J4: 3.31 | K4: 35.82
A5: 4 | B5: Wii Sports Resort | C5: Wii | D5: 2009 | E5: Sports | F5: Nintendo | G5: 15.75 | H5: 11.01 | I5: 3.28 | J5: 2.96 | K5: 33
A6: 5 | B6: Pokemon Red/Pokemon Blue | C6: GB | D6: 1996 | E6: Role-Playing | F6: Nintendo | G6: 11.27 | H6: 8.89 | I6: 10.22 | J6: 1 | K6: 31.37
A7: 6 | B7: Tetris | C7: GB | D7: 1989 | E7: Puzzle | F7: Nintendo | G7: 23.2 | H7: 2.26 | I7: 4.22 | J7: 0.58 | K7: 30.26
A8: 7 | B8: New Super Mario Bros. | C8: DS | D8: 2006 | E8: Platform | F8: Nintendo | G8: 11.38 | H8: 9.23 | I8: 6.5 | J8: 2.9 | K8: 30.01
A9: 8 | B9: Wii Play | C9: Wii | D9: 2006 | E9: Misc | F9: Nintendo | G9: 14.03 | H9: 9.2 | I9: 2.93 | J9: 2.85 | K9: 29.02
A10: 9 | B10: New Super Mario Bros. Wii | C10: Wii | D10: 2009 | E10: Platform | F10: Nintendo | G10: 14.59 | H10: 7.06 | I10: 4.7 | J10: 2.26 | K10: 28.62
A11: 10 | B11: Duck Hunt | C11: NES | D11: 1984 | E11: Shooter | F11: Nintendo | G11: 26.93 | H11: 0.63 | I11: 0.28 | J11: 0.47 | K11: 28.31
A12: 11 | B12: Nintendogs | C12: DS | D12: 2005 | E12: Simulation | F12: Nintendo | G12: 9.07 | H12: 11 | I12: 1.93 | J12: 2.75 | K12: 24.76
A13: 12 | B13: Mario Kart DS | C13: DS | D13: 2005 | E13: Racing | F13: Nintendo | G13: 9.81 | H13: 7.57 | I13: 4.13 | J13: 1.92 | K13: 23.42
... A101: 100 | B101: Battlefield 3 | C101: X360 | D101: 2011 | E101: Shooter | F101: Electronic Arts | G101: 4.46 | H101: 2.13 | I101: 0.06 | J101: 0.69 | K101: 7.34

Sheet Summary
B2: Data Summary — Video Game Sales (Top 100)
B3: Sumber: Dataset sheet | Dibuat otomatis dari 100 baris data
B5: Ringkasan Umum
B6: Jumlah Baris Data | D6: =COUNTA(Dataset!A2:A101) -> 100
B7: Jumlah Kolom | D7: =11 -> 11
B8: Missing Values | D8: =SUMPRODUCT((Dataset!A2:K101="")*1) -> 0
B9: Judul Game Muncul >1x (Multi-Platform) | D9: =SUMPRODUCT((COUNTIF(Dataset!B2:B101,Dataset!B2:B101)>1)*1) -> 17
B10: Tahun Rilis Tertua | D10: =MIN(Dataset!D2:D101) -> 1982
B11: Tahun Rilis Terbaru | D11: =MAX(Dataset!D2:D101) -> 2015
B13: Total Penjualan per Region (juta unit)
B14: NA_Sales | D14: =SUM(Dataset!G2:G101) -> 704.99
B15: EU_Sales | D15: =SUM(Dataset!H2:H101) -> 420.66
B16: JP_Sales | D16: =SUM(Dataset!I2:I101) -> 204.62
B17: Other_Sales | D17: =SUM(Dataset!J2:J101) -> 131.77
B18: Global_Sales | D18: =SUM(Dataset!K2:K101) -> 1461.98
B20: Rata-rata Global Sales | D20: =AVERAGE(Dataset!K2:K101) -> 14.6198
B21: Global Sales Tertinggi | D21: =MAX(Dataset!K2:K101) -> 82.74
B22: Global Sales Terendah | D22: =MIN(Dataset!K2:K101) -> 7.34
B24: Top 5 Game Berdasarkan Global Sales
B25: Rank | C25: Name | D25: Platform | E25: Global_Sales
B26: =INDEX(Dataset!A2:A101,MATCH(LARGE(Dataset!K2:K101,1),Dataset!K2:K101,0)) -> 1 | C26: =INDEX(Dataset!B2:B101,MATCH(LARGE(Dataset!K2:K101,1),Dataset!K2:K101,0)) -> Wii Sports | D26: =INDEX(Dataset!C2:C101,MATCH(LARGE(Dataset!K2:K101,1),Dataset!K2:K101,0)) -> Wii | E26: =LARGE(Dataset!K2:K101,1) -> 82.74
B27: =INDEX(Dataset!A2:A101,MATCH(LARGE(Dataset!K2:K101,2),Dataset!K2:K101,0)) -> 2 | C27: =INDEX(Dataset!B2:B101,MATCH(LARGE(Dataset!K2:K101,2),Dataset!K2:K101,0)) -> Super Mario Bros. | D27: =INDEX(Dataset!C2:C101,MATCH(LARGE(Dataset!K2:K101,2),Dataset!K2:K101,0)) -> NES | E27: =LARGE(Dataset!K2:K101,2) -> 40.24
B28: =INDEX(Dataset!A2:A101,MATCH(LARGE(Dataset!K2:K101,3),Dataset!K2:K101,0)) -> 3 | C28: =INDEX(Dataset!B2:B101,MATCH(LARGE(Dataset!K2:K101,3),Dataset!K2:K101,0)) -> Mario Kart Wii | D28: =INDEX(Dataset!C2:C101,MATCH(LARGE(Dataset!K2:K101,3),Dataset!K2:K101,0)) -> Wii | E28: =LARGE(Dataset!K2:K101,3) -> 35.82
B29: =INDEX(Dataset!A2:A101,MATCH(LARGE(Dataset!K2:K101,4),Dataset!K2:K101,0)) -> 4 | C29: =INDEX(Dataset!B2:B101,MATCH(LARGE(Dataset!K2:K101,4),Dataset!K2:K101,0)) -> Wii Sports Resort | D29: =INDEX(Dataset!C2:C101,MATCH(LARGE(Dataset!K2:K101,4),Dataset!K2:K101,0)) -> Wii | E29: =LARGE(Dataset!K2:K101,4) -> 33
B30: =INDEX(Dataset!A2:A101,MATCH(LARGE(Dataset!K2:K101,5),Dataset!K2:K101,0)) -> 5 | C30: =INDEX(Dataset!B2:B101,MATCH(LARGE(Dataset!K2:K101,5),Dataset!K2:K101,0)) -> Pokemon Red/Pokemon Blue | D30: =INDEX(Dataset!C2:C101,MATCH(LARGE(Dataset!K2:K101,5),Dataset!K2:K101,0)) -> GB | E30: =LARGE(Dataset!K2:K101,5) -> 31.37
B33: Distribusi Genre (Jumlah Game & Total Global Sales)
B34: Genre | C34: Jumlah Game | D34: Total Global Sales
B35: Shooter | C35: =COUNTIF(Dataset!E2:E101,B35) -> 22 | D35: =SUMIF(Dataset!E2:E101,B35,Dataset!K2:K101) -> 257.56
B36: Platform | C36: =COUNTIF(Dataset!E2:E101,B36) -> 16 | D36: =SUMIF(Dataset!E2:E101,B36,Dataset!K2:K101) -> 251.92
B37: Role-Playing | C37: =COUNTIF(Dataset!E2:E101,B37) -> 15 | D37: =SUMIF(Dataset!E2:E101,B37,Dataset!K2:K101) -> 205.45
B38: Action | C38: =COUNTIF(Dataset!E2:E101,B38) -> 12 | D38: =SUMIF(Dataset!E2:E101,B38,Dataset!K2:K101) -> 156.87
B39: Racing | C39: =COUNTIF(Dataset!E2:E101,B39) -> 10 | D39: =SUMIF(Dataset!E2:E101,B39,Dataset!K2:K101) -> 147.93
B40: Misc | C40: =COUNTIF(Dataset!E2:E101,B40) -> 9 | D40: =SUMIF(Dataset!E2:E101,B40,Dataset!K2:K101) -> 125.97
B41: Sports | C41: =COUNTIF(Dataset!E2:E101,B41) -> 6 | D41: =SUMIF(Dataset!E2:E101,B41,Dataset!K2:K101) -> 177.01
B42: Simulation | C42: =COUNTIF(Dataset!E2:E101,B42) -> 4 | D42: =SUMIF(Dataset!E2:E101,B42,Dataset!K2:K101) -> 54.23
B43: Puzzle | C43: =COUNTIF(Dataset!E2:E101,B43) -> 3 | D43: =SUMIF(Dataset!E2:E101,B43,Dataset!K2:K101) -> 53.37
B44: Fighting | C44: =COUNTIF(Dataset!E2:E101,B44) -> 2 | D44: =SUMIF(Dataset!E2:E101,B44,Dataset!K2:K101) -> 20.49
B45: Adventure | C45: =COUNTIF(Dataset!E2:E101,B45) -> 1 | D45: =SUMIF(Dataset!E2:E101,B45,Dataset!K2:K101) -> 11.18
B48: Distribusi Platform (Jumlah Game & Total Global Sales)
B49: Platform | C49: Jumlah Game | D49: Total Global Sales
...
